package br.com.tecnonoticias.myException;

public class Cliente {

	public String teste1() {
//		new ClienteComum().cadastro("falha");
		return "falha";
	}
	public String teste2(){
//		new ClienteExpecial().cadastro("falha");
		return "falha";
	}
	
	public static void main(String[] args) {
		ClienteComum cC = new ClienteComum();
		cC.cadastro(cC.teste1());
		
	}

//	public static void main(String[] args) {
//		try {
//			new Cliente().teste1();
//		} catch (Exception e) {
//			System.out.println("Encontrado uma falha no teste1! ");
//		}
//		
//		try {
//			new Cliente().teste2();
//		} catch (Exception e) {
//			System.out.println("Encontrada uma falha no teste2! ");
//		}
//	}

}

class ClienteComum extends Cliente {
	
	public void cadastro(String falha) throws IllegalArgumentException{
//		if (falha.equals("falha")) {
			IllegalArgumentException illegalArgumentException = new IllegalArgumentException();
			throw illegalArgumentException;
//		}else{
//			System.out.println("Passou no teste1 ");
//		}
	}
}

class ClienteExpecial extends Cliente {
	
	public void cadastro(String falha) throws IllegalArgumentException{
//		if (falha.equals("falha")) {
			throw new IllegalArgumentException(falha);
//		}else{
//			System.out.println("Passou no teste2 ");
//		}
	}

}

class Main {
	
	
	
}
